Creating test database for alias 'default' ('file:memorydb_default?mode=memory&cache=shared')...
Found 45 test(s).
Operations to perform:
  Synchronize unmigrated apps: messages, rest_framework, staticfiles
  Apply all migrations: address, admin, auth, authtoken, contenttypes, courses, sessions, users
Synchronizing apps without migrations:
  Creating tables...
    Running deferred SQL...
Running migrations:
  Applying contenttypes.0001_initial... OK
  Applying contenttypes.0002_remove_content_type_name... OK
  Applying auth.0001_initial... OK
  Applying auth.0002_alter_permission_name_max_length... OK
  Applying auth.0003_alter_user_email_max_length... OK
  Applying auth.0004_alter_user_username_opts... OK
  Applying auth.0005_alter_user_last_login_null... OK
  Applying auth.0006_require_contenttypes_0002... OK
  Applying auth.0007_alter_validators_add_error_messages... OK
  Applying auth.0008_alter_user_username_max_length... OK
  Applying auth.0009_alter_user_last_name_max_length... OK
  Applying auth.0010_alter_group_name_max_length... OK
  Applying auth.0011_update_proxy_permissions... OK
  Applying auth.0012_alter_user_first_name_max_length... OK
  Applying users.0001_initial... OK
  Applying address.0001_initial... OK
  Applying address.0002_initial... OK
  Applying admin.0001_initial... OK
  Applying admin.0002_logentry_remove_auto_add... OK
  Applying admin.0003_logentry_add_action_flag_choices... OK
  Applying authtoken.0001_initial... OK
  Applying authtoken.0002_auto_20160226_1747... OK
  Applying authtoken.0003_tokenproxy... OK
  Applying courses.0001_initial... OK
  Applying sessions.0001_initial... OK
System check identified no issues (0 silenced).
test_duplicate_email_user_creation_422 (test_api.TestAccountsRoutesWithoutAuthentication) ... ok
test_instructor_user_creation_201 (test_api.TestAccountsRoutesWithoutAuthentication) ... ok
test_list_users_by_instructor_200 (test_api.TestAccountsRoutesWithoutAuthentication) ... ok
test_list_users_by_student_403 (test_api.TestAccountsRoutesWithoutAuthentication) ... ok
test_list_users_with_no_token_401 (test_api.TestAccountsRoutesWithoutAuthentication) ... ok
test_login_success_200 (test_api.TestAccountsRoutesWithoutAuthentication) ... ok
test_login_with_invalid_credentials_401 (test_api.TestAccountsRoutesWithoutAuthentication) ... ok
test_login_with_wrong_fields_400 (test_api.TestAccountsRoutesWithoutAuthentication) ... FAIL
test_student_user_creation_201 (test_api.TestAccountsRoutesWithoutAuthentication) ... ok
test_wrong_data_user_creation_400 (test_api.TestAccountsRoutesWithoutAuthentication) ... FAIL
test_address_creation_200 (test_api.TestAddress) ... ERROR
test_address_creation_already_exists_200 (test_api.TestAddress) ... ERROR
test_address_creation_wrong_data_400 (test_api.TestAddress) ... ERROR
test_delete_course_by_instructor_204 (test_api.TestCourseDelete) ... /home/keila/q4/entregas/parte2-django/entrega10/venv/lib/python3.9/site-packages/django/db/models/fields/__init__.py:1534: RuntimeWarning: DateTimeField Course.created_at received a naive datetime (2022-03-16 02:39:35.965118) while time zone support is active.
  warnings.warn(
FAIL
test_delete_course_by_no_user_401 (test_api.TestCourseDelete) ... /home/keila/q4/entregas/parte2-django/entrega10/venv/lib/python3.9/site-packages/django/db/models/fields/__init__.py:1534: RuntimeWarning: DateTimeField Course.created_at received a naive datetime (2022-03-16 02:39:36.733205) while time zone support is active.
  warnings.warn(
FAIL
test_delete_course_by_student_403 (test_api.TestCourseDelete) ... /home/keila/q4/entregas/parte2-django/entrega10/venv/lib/python3.9/site-packages/django/db/models/fields/__init__.py:1534: RuntimeWarning: DateTimeField Course.created_at received a naive datetime (2022-03-16 02:39:37.312905) while time zone support is active.
  warnings.warn(
FAIL
test_delete_course_with_invalid_course_id_404 (test_api.TestCourseDelete) ... /home/keila/q4/entregas/parte2-django/entrega10/venv/lib/python3.9/site-packages/django/db/models/fields/__init__.py:1534: RuntimeWarning: DateTimeField Course.created_at received a naive datetime (2022-03-16 02:39:38.078574) while time zone support is active.
  warnings.warn(
FAIL
test_course_creation_by_instructor_201 (test_api.TestCoursesCreation) ... /home/keila/q4/entregas/parte2-django/entrega10/venv/lib/python3.9/site-packages/django/db/models/fields/__init__.py:1534: RuntimeWarning: DateTimeField Course.created_at received a naive datetime (2022-03-16 02:39:38.850937) while time zone support is active.
  warnings.warn(
FAIL
test_course_creation_by_no_user_401 (test_api.TestCoursesCreation) ... /home/keila/q4/entregas/parte2-django/entrega10/venv/lib/python3.9/site-packages/django/db/models/fields/__init__.py:1534: RuntimeWarning: DateTimeField Course.created_at received a naive datetime (2022-03-16 02:39:39.254645) while time zone support is active.
  warnings.warn(
FAIL
test_course_creation_by_student_403 (test_api.TestCoursesCreation) ... /home/keila/q4/entregas/parte2-django/entrega10/venv/lib/python3.9/site-packages/django/db/models/fields/__init__.py:1534: RuntimeWarning: DateTimeField Course.created_at received a naive datetime (2022-03-16 02:39:39.880476) while time zone support is active.
  warnings.warn(
FAIL
test_course_creation_duplicate_name_422 (test_api.TestCoursesCreation) ... /home/keila/q4/entregas/parte2-django/entrega10/venv/lib/python3.9/site-packages/django/db/models/fields/__init__.py:1534: RuntimeWarning: DateTimeField Course.created_at received a naive datetime (2022-03-16 02:39:40.495249) while time zone support is active.
  warnings.warn(
ok
test_course_creation_wrong_data_400 (test_api.TestCoursesCreation) ... FAIL
test_list_courses_200 (test_api.TestCoursesCreation) ... /home/keila/q4/entregas/parte2-django/entrega10/venv/lib/python3.9/site-packages/django/db/models/fields/__init__.py:1534: RuntimeWarning: DateTimeField Course.created_at received a naive datetime (2022-03-16 02:39:41.804057) while time zone support is active.
  warnings.warn(
ok
test_retrieve_invalid_course_404 (test_api.TestCoursesCreation) ... ERROR
test_retrieve_valid_course_200 (test_api.TestCoursesCreation) ... /home/keila/q4/entregas/parte2-django/entrega10/venv/lib/python3.9/site-packages/django/db/models/fields/__init__.py:1534: RuntimeWarning: DateTimeField Course.created_at received a naive datetime (2022-03-16 02:39:42.831901) while time zone support is active.
  warnings.warn(
FAIL
test_register_instructor_course_by_instructor_200 (test_api.TestCoursesRegister) ... /home/keila/q4/entregas/parte2-django/entrega10/venv/lib/python3.9/site-packages/django/db/models/fields/__init__.py:1534: RuntimeWarning: DateTimeField Course.created_at received a naive datetime (2022-03-16 02:39:43.598099) while time zone support is active.
  warnings.warn(
ERROR
test_register_instructor_course_by_no_user_401 (test_api.TestCoursesRegister) ... /home/keila/q4/entregas/parte2-django/entrega10/venv/lib/python3.9/site-packages/django/db/models/fields/__init__.py:1534: RuntimeWarning: DateTimeField Course.created_at received a naive datetime (2022-03-16 02:39:44.546918) while time zone support is active.
  warnings.warn(
ERROR
test_register_instructor_course_by_student_403 (test_api.TestCoursesRegister) ... /home/keila/q4/entregas/parte2-django/entrega10/venv/lib/python3.9/site-packages/django/db/models/fields/__init__.py:1534: RuntimeWarning: DateTimeField Course.created_at received a naive datetime (2022-03-16 02:39:45.311722) while time zone support is active.
  warnings.warn(
ERROR
test_register_instructor_course_with_invalid_id_404 (test_api.TestCoursesRegister) ... /home/keila/q4/entregas/parte2-django/entrega10/venv/lib/python3.9/site-packages/django/db/models/fields/__init__.py:1534: RuntimeWarning: DateTimeField Course.created_at received a naive datetime (2022-03-16 02:39:46.265590) while time zone support is active.
  warnings.warn(
ERROR
test_register_instructor_course_with_student_id_422 (test_api.TestCoursesRegister) ... /home/keila/q4/entregas/parte2-django/entrega10/venv/lib/python3.9/site-packages/django/db/models/fields/__init__.py:1534: RuntimeWarning: DateTimeField Course.created_at received a naive datetime (2022-03-16 02:39:47.215886) while time zone support is active.
  warnings.warn(
ERROR
test_register_instructor_course_with_wrong_field_400 (test_api.TestCoursesRegister) ... /home/keila/q4/entregas/parte2-django/entrega10/venv/lib/python3.9/site-packages/django/db/models/fields/__init__.py:1534: RuntimeWarning: DateTimeField Course.created_at received a naive datetime (2022-03-16 02:39:48.161939) while time zone support is active.
  warnings.warn(
ERROR
test_register_instructor_course_wrong_courseId_404 (test_api.TestCoursesRegister) ... /home/keila/q4/entregas/parte2-django/entrega10/venv/lib/python3.9/site-packages/django/db/models/fields/__init__.py:1534: RuntimeWarning: DateTimeField Course.created_at received a naive datetime (2022-03-16 02:39:49.110295) while time zone support is active.
  warnings.warn(
ERROR
test_register_students_course_by_intructor_200 (test_api.TestCoursesRegister) ... /home/keila/q4/entregas/parte2-django/entrega10/venv/lib/python3.9/site-packages/django/db/models/fields/__init__.py:1534: RuntimeWarning: DateTimeField Course.created_at received a naive datetime (2022-03-16 02:39:50.063962) while time zone support is active.
  warnings.warn(
ERROR
test_register_students_course_by_no_user_401 (test_api.TestCoursesRegister) ... /home/keila/q4/entregas/parte2-django/entrega10/venv/lib/python3.9/site-packages/django/db/models/fields/__init__.py:1534: RuntimeWarning: DateTimeField Course.created_at received a naive datetime (2022-03-16 02:39:51.012952) while time zone support is active.
  warnings.warn(
ERROR
test_register_students_course_by_student_403 (test_api.TestCoursesRegister) ... /home/keila/q4/entregas/parte2-django/entrega10/venv/lib/python3.9/site-packages/django/db/models/fields/__init__.py:1534: RuntimeWarning: DateTimeField Course.created_at received a naive datetime (2022-03-16 02:39:51.777319) while time zone support is active.
  warnings.warn(
ERROR
test_register_students_course_invalid_course_id_404 (test_api.TestCoursesRegister) ... /home/keila/q4/entregas/parte2-django/entrega10/venv/lib/python3.9/site-packages/django/db/models/fields/__init__.py:1534: RuntimeWarning: DateTimeField Course.created_at received a naive datetime (2022-03-16 02:39:52.723580) while time zone support is active.
  warnings.warn(
ERROR
test_register_students_course_with_instructor_id_422 (test_api.TestCoursesRegister) ... /home/keila/q4/entregas/parte2-django/entrega10/venv/lib/python3.9/site-packages/django/db/models/fields/__init__.py:1534: RuntimeWarning: DateTimeField Course.created_at received a naive datetime (2022-03-16 02:39:53.669715) while time zone support is active.
  warnings.warn(
ERROR
test_register_students_course_with_invalid_student_id_404 (test_api.TestCoursesRegister) ... /home/keila/q4/entregas/parte2-django/entrega10/venv/lib/python3.9/site-packages/django/db/models/fields/__init__.py:1534: RuntimeWarning: DateTimeField Course.created_at received a naive datetime (2022-03-16 02:39:54.616077) while time zone support is active.
  warnings.warn(
ERROR
test_register_students_course_with_wrong_field_400 (test_api.TestCoursesRegister) ... /home/keila/q4/entregas/parte2-django/entrega10/venv/lib/python3.9/site-packages/django/db/models/fields/__init__.py:1534: RuntimeWarning: DateTimeField Course.created_at received a naive datetime (2022-03-16 02:39:55.562519) while time zone support is active.
  warnings.warn(
ERROR
test_register_students_course_with_wrong_field_type_400 (test_api.TestCoursesRegister) ... /home/keila/q4/entregas/parte2-django/entrega10/venv/lib/python3.9/site-packages/django/db/models/fields/__init__.py:1534: RuntimeWarning: DateTimeField Course.created_at received a naive datetime (2022-03-16 02:39:56.508729) while time zone support is active.
  warnings.warn(
ERROR
test_update_course_by_instructor_200 (test_api.TestCoursesUpdate) ... /home/keila/q4/entregas/parte2-django/entrega10/venv/lib/python3.9/site-packages/django/db/models/fields/__init__.py:1534: RuntimeWarning: DateTimeField Course.created_at received a naive datetime (2022-03-16 02:39:57.086934) while time zone support is active.
  warnings.warn(
FAIL
test_update_course_by_no_user_401 (test_api.TestCoursesUpdate) ... /home/keila/q4/entregas/parte2-django/entrega10/venv/lib/python3.9/site-packages/django/db/models/fields/__init__.py:1534: RuntimeWarning: DateTimeField Course.created_at received a naive datetime (2022-03-16 02:39:57.849560) while time zone support is active.
  warnings.warn(
FAIL
test_update_course_by_student_403 (test_api.TestCoursesUpdate) ... /home/keila/q4/entregas/parte2-django/entrega10/venv/lib/python3.9/site-packages/django/db/models/fields/__init__.py:1534: RuntimeWarning: DateTimeField Course.created_at received a naive datetime (2022-03-16 02:39:58.430302) while time zone support is active.
  warnings.warn(
FAIL
test_update_course_with_conflict_422 (test_api.TestCoursesUpdate) ... /home/keila/q4/entregas/parte2-django/entrega10/venv/lib/python3.9/site-packages/django/db/models/fields/__init__.py:1534: RuntimeWarning: DateTimeField Course.created_at received a naive datetime (2022-03-16 02:39:59.193522) while time zone support is active.
  warnings.warn(
/home/keila/q4/entregas/parte2-django/entrega10/venv/lib/python3.9/site-packages/django/db/models/fields/__init__.py:1534: RuntimeWarning: DateTimeField Course.created_at received a naive datetime (2022-03-16 02:39:59.561851) while time zone support is active.
  warnings.warn(
FAIL
test_update_invalid_course_404 (test_api.TestCoursesUpdate) ... /home/keila/q4/entregas/parte2-django/entrega10/venv/lib/python3.9/site-packages/django/db/models/fields/__init__.py:1534: RuntimeWarning: DateTimeField Course.created_at received a naive datetime (2022-03-16 02:39:59.957496) while time zone support is active.
  warnings.warn(
FAIL

======================================================================
ERROR: test_address_creation_200 (test_api.TestAddress)
----------------------------------------------------------------------
Traceback (most recent call last):
  File "/home/keila/q4/entregas/parte2-django/entrega10/test_api.py", line 1223, in test_address_creation_200
    output = response.json()
  File "/home/keila/q4/entregas/parte2-django/entrega10/venv/lib/python3.9/site-packages/django/test/client.py", line 748, in _parse_json
    raise ValueError(
ValueError: Content-Type header is "text/html", not "application/json"

======================================================================
ERROR: test_address_creation_already_exists_200 (test_api.TestAddress)
----------------------------------------------------------------------
Traceback (most recent call last):
  File "/home/keila/q4/entregas/parte2-django/entrega10/test_api.py", line 1246, in test_address_creation_already_exists_200
    output = response.json()
  File "/home/keila/q4/entregas/parte2-django/entrega10/venv/lib/python3.9/site-packages/django/test/client.py", line 748, in _parse_json
    raise ValueError(
ValueError: Content-Type header is "text/html", not "application/json"

======================================================================
ERROR: test_address_creation_wrong_data_400 (test_api.TestAddress)
----------------------------------------------------------------------
Traceback (most recent call last):
  File "/home/keila/q4/entregas/parte2-django/entrega10/test_api.py", line 1273, in test_address_creation_wrong_data_400
    output = response.json()
  File "/home/keila/q4/entregas/parte2-django/entrega10/venv/lib/python3.9/site-packages/django/test/client.py", line 748, in _parse_json
    raise ValueError(
ValueError: Content-Type header is "text/html", not "application/json"

======================================================================
ERROR: test_retrieve_invalid_course_404 (test_api.TestCoursesCreation)
----------------------------------------------------------------------
Traceback (most recent call last):
  File "/home/keila/q4/entregas/parte2-django/entrega10/test_api.py", line 372, in test_retrieve_invalid_course_404
    response = self.client.get(f"/api/courses/{uuid}/", format="json")
  File "/home/keila/q4/entregas/parte2-django/entrega10/venv/lib/python3.9/site-packages/rest_framework/test.py", line 289, in get
    response = super().get(path, data=data, **extra)
  File "/home/keila/q4/entregas/parte2-django/entrega10/venv/lib/python3.9/site-packages/rest_framework/test.py", line 206, in get
    return self.generic('GET', path, **r)
  File "/home/keila/q4/entregas/parte2-django/entrega10/venv/lib/python3.9/site-packages/rest_framework/test.py", line 234, in generic
    return super().generic(
  File "/home/keila/q4/entregas/parte2-django/entrega10/venv/lib/python3.9/site-packages/django/test/client.py", line 541, in generic
    return self.request(**r)
  File "/home/keila/q4/entregas/parte2-django/entrega10/venv/lib/python3.9/site-packages/rest_framework/test.py", line 286, in request
    return super().request(**kwargs)
  File "/home/keila/q4/entregas/parte2-django/entrega10/venv/lib/python3.9/site-packages/rest_framework/test.py", line 238, in request
    request = super().request(**kwargs)
  File "/home/keila/q4/entregas/parte2-django/entrega10/venv/lib/python3.9/site-packages/django/test/client.py", line 810, in request
    self.check_exception(response)
  File "/home/keila/q4/entregas/parte2-django/entrega10/venv/lib/python3.9/site-packages/django/test/client.py", line 663, in check_exception
    raise exc_value
  File "/home/keila/q4/entregas/parte2-django/entrega10/venv/lib/python3.9/site-packages/django/core/handlers/exception.py", line 55, in inner
    response = get_response(request)
  File "/home/keila/q4/entregas/parte2-django/entrega10/venv/lib/python3.9/site-packages/django/core/handlers/base.py", line 197, in _get_response
    response = wrapped_callback(request, *callback_args, **callback_kwargs)
  File "/home/keila/q4/entregas/parte2-django/entrega10/venv/lib/python3.9/site-packages/django/views/decorators/csrf.py", line 54, in wrapped_view
    return view_func(*args, **kwargs)
  File "/home/keila/q4/entregas/parte2-django/entrega10/venv/lib/python3.9/site-packages/django/views/generic/base.py", line 84, in view
    return self.dispatch(request, *args, **kwargs)
  File "/home/keila/q4/entregas/parte2-django/entrega10/venv/lib/python3.9/site-packages/rest_framework/views.py", line 509, in dispatch
    response = self.handle_exception(exc)
  File "/home/keila/q4/entregas/parte2-django/entrega10/venv/lib/python3.9/site-packages/rest_framework/views.py", line 469, in handle_exception
    self.raise_uncaught_exception(exc)
  File "/home/keila/q4/entregas/parte2-django/entrega10/venv/lib/python3.9/site-packages/rest_framework/views.py", line 480, in raise_uncaught_exception
    raise exc
  File "/home/keila/q4/entregas/parte2-django/entrega10/venv/lib/python3.9/site-packages/rest_framework/views.py", line 506, in dispatch
    response = handler(request, *args, **kwargs)
  File "/home/keila/q4/entregas/parte2-django/entrega10/courses/views.py", line 62, in get
    course = Course.objects.get(uuid=course_id)
  File "/home/keila/q4/entregas/parte2-django/entrega10/venv/lib/python3.9/site-packages/django/db/models/manager.py", line 85, in manager_method
    return getattr(self.get_queryset(), name)(*args, **kwargs)
  File "/home/keila/q4/entregas/parte2-django/entrega10/venv/lib/python3.9/site-packages/django/db/models/query.py", line 496, in get
    raise self.model.DoesNotExist(
courses.models.Course.DoesNotExist: Course matching query does not exist.

======================================================================
ERROR: test_register_instructor_course_by_instructor_200 (test_api.TestCoursesRegister)
----------------------------------------------------------------------
Traceback (most recent call last):
  File "/home/keila/q4/entregas/parte2-django/entrega10/test_api.py", line 630, in test_register_instructor_course_by_instructor_200
    output = response.json()
  File "/home/keila/q4/entregas/parte2-django/entrega10/venv/lib/python3.9/site-packages/django/test/client.py", line 748, in _parse_json
    raise ValueError(
ValueError: Content-Type header is "text/html", not "application/json"

======================================================================
ERROR: test_register_instructor_course_by_no_user_401 (test_api.TestCoursesRegister)
----------------------------------------------------------------------
Traceback (most recent call last):
  File "/home/keila/q4/entregas/parte2-django/entrega10/test_api.py", line 707, in test_register_instructor_course_by_no_user_401
    output = response.json()
  File "/home/keila/q4/entregas/parte2-django/entrega10/venv/lib/python3.9/site-packages/django/test/client.py", line 748, in _parse_json
    raise ValueError(
ValueError: Content-Type header is "text/html", not "application/json"

======================================================================
ERROR: test_register_instructor_course_by_student_403 (test_api.TestCoursesRegister)
----------------------------------------------------------------------
Traceback (most recent call last):
  File "/home/keila/q4/entregas/parte2-django/entrega10/test_api.py", line 687, in test_register_instructor_course_by_student_403
    output = response.json()
  File "/home/keila/q4/entregas/parte2-django/entrega10/venv/lib/python3.9/site-packages/django/test/client.py", line 748, in _parse_json
    raise ValueError(
ValueError: Content-Type header is "text/html", not "application/json"

======================================================================
ERROR: test_register_instructor_course_with_invalid_id_404 (test_api.TestCoursesRegister)
----------------------------------------------------------------------
Traceback (most recent call last):
  File "/home/keila/q4/entregas/parte2-django/entrega10/test_api.py", line 776, in test_register_instructor_course_with_invalid_id_404
    output = response.json()
  File "/home/keila/q4/entregas/parte2-django/entrega10/venv/lib/python3.9/site-packages/django/test/client.py", line 748, in _parse_json
    raise ValueError(
ValueError: Content-Type header is "text/html", not "application/json"

======================================================================
ERROR: test_register_instructor_course_with_student_id_422 (test_api.TestCoursesRegister)
----------------------------------------------------------------------
Traceback (most recent call last):
  File "/home/keila/q4/entregas/parte2-django/entrega10/test_api.py", line 751, in test_register_instructor_course_with_student_id_422
    output = response.json()
  File "/home/keila/q4/entregas/parte2-django/entrega10/venv/lib/python3.9/site-packages/django/test/client.py", line 748, in _parse_json
    raise ValueError(
ValueError: Content-Type header is "text/html", not "application/json"

======================================================================
ERROR: test_register_instructor_course_with_wrong_field_400 (test_api.TestCoursesRegister)
----------------------------------------------------------------------
Traceback (most recent call last):
  File "/home/keila/q4/entregas/parte2-django/entrega10/test_api.py", line 801, in test_register_instructor_course_with_wrong_field_400
    output = response.json()
  File "/home/keila/q4/entregas/parte2-django/entrega10/venv/lib/python3.9/site-packages/django/test/client.py", line 748, in _parse_json
    raise ValueError(
ValueError: Content-Type header is "text/html", not "application/json"

======================================================================
ERROR: test_register_instructor_course_wrong_courseId_404 (test_api.TestCoursesRegister)
----------------------------------------------------------------------
Traceback (most recent call last):
  File "/home/keila/q4/entregas/parte2-django/entrega10/test_api.py", line 731, in test_register_instructor_course_wrong_courseId_404
    output = response.json()
  File "/home/keila/q4/entregas/parte2-django/entrega10/venv/lib/python3.9/site-packages/django/test/client.py", line 748, in _parse_json
    raise ValueError(
ValueError: Content-Type header is "text/html", not "application/json"

======================================================================
ERROR: test_register_students_course_by_intructor_200 (test_api.TestCoursesRegister)
----------------------------------------------------------------------
Traceback (most recent call last):
  File "/home/keila/q4/entregas/parte2-django/entrega10/test_api.py", line 829, in test_register_students_course_by_intructor_200
    output = response.json()
  File "/home/keila/q4/entregas/parte2-django/entrega10/venv/lib/python3.9/site-packages/django/test/client.py", line 748, in _parse_json
    raise ValueError(
ValueError: Content-Type header is "text/html", not "application/json"

======================================================================
ERROR: test_register_students_course_by_no_user_401 (test_api.TestCoursesRegister)
----------------------------------------------------------------------
Traceback (most recent call last):
  File "/home/keila/q4/entregas/parte2-django/entrega10/test_api.py", line 894, in test_register_students_course_by_no_user_401
    output = response.json()
  File "/home/keila/q4/entregas/parte2-django/entrega10/venv/lib/python3.9/site-packages/django/test/client.py", line 748, in _parse_json
    raise ValueError(
ValueError: Content-Type header is "text/html", not "application/json"

======================================================================
ERROR: test_register_students_course_by_student_403 (test_api.TestCoursesRegister)
----------------------------------------------------------------------
Traceback (most recent call last):
  File "/home/keila/q4/entregas/parte2-django/entrega10/test_api.py", line 872, in test_register_students_course_by_student_403
    output = response.json()
  File "/home/keila/q4/entregas/parte2-django/entrega10/venv/lib/python3.9/site-packages/django/test/client.py", line 748, in _parse_json
    raise ValueError(
ValueError: Content-Type header is "text/html", not "application/json"

======================================================================
ERROR: test_register_students_course_invalid_course_id_404 (test_api.TestCoursesRegister)
----------------------------------------------------------------------
Traceback (most recent call last):
  File "/home/keila/q4/entregas/parte2-django/entrega10/test_api.py", line 919, in test_register_students_course_invalid_course_id_404
    output = response.json()
  File "/home/keila/q4/entregas/parte2-django/entrega10/venv/lib/python3.9/site-packages/django/test/client.py", line 748, in _parse_json
    raise ValueError(
ValueError: Content-Type header is "text/html", not "application/json"

======================================================================
ERROR: test_register_students_course_with_instructor_id_422 (test_api.TestCoursesRegister)
----------------------------------------------------------------------
Traceback (most recent call last):
  File "/home/keila/q4/entregas/parte2-django/entrega10/test_api.py", line 969, in test_register_students_course_with_instructor_id_422
    output = response.json()
  File "/home/keila/q4/entregas/parte2-django/entrega10/venv/lib/python3.9/site-packages/django/test/client.py", line 748, in _parse_json
    raise ValueError(
ValueError: Content-Type header is "text/html", not "application/json"

======================================================================
ERROR: test_register_students_course_with_invalid_student_id_404 (test_api.TestCoursesRegister)
----------------------------------------------------------------------
Traceback (most recent call last):
  File "/home/keila/q4/entregas/parte2-django/entrega10/test_api.py", line 944, in test_register_students_course_with_invalid_student_id_404
    output = response.json()
  File "/home/keila/q4/entregas/parte2-django/entrega10/venv/lib/python3.9/site-packages/django/test/client.py", line 748, in _parse_json
    raise ValueError(
ValueError: Content-Type header is "text/html", not "application/json"

======================================================================
ERROR: test_register_students_course_with_wrong_field_400 (test_api.TestCoursesRegister)
----------------------------------------------------------------------
Traceback (most recent call last):
  File "/home/keila/q4/entregas/parte2-django/entrega10/test_api.py", line 994, in test_register_students_course_with_wrong_field_400
    output = response.json()
  File "/home/keila/q4/entregas/parte2-django/entrega10/venv/lib/python3.9/site-packages/django/test/client.py", line 748, in _parse_json
    raise ValueError(
ValueError: Content-Type header is "text/html", not "application/json"

======================================================================
ERROR: test_register_students_course_with_wrong_field_type_400 (test_api.TestCoursesRegister)
----------------------------------------------------------------------
Traceback (most recent call last):
  File "/home/keila/q4/entregas/parte2-django/entrega10/test_api.py", line 1019, in test_register_students_course_with_wrong_field_type_400
    output = response.json()
  File "/home/keila/q4/entregas/parte2-django/entrega10/venv/lib/python3.9/site-packages/django/test/client.py", line 748, in _parse_json
    raise ValueError(
ValueError: Content-Type header is "text/html", not "application/json"

======================================================================
FAIL: test_login_with_wrong_fields_400 (test_api.TestAccountsRoutesWithoutAuthentication)
----------------------------------------------------------------------
Traceback (most recent call last):
  File "/home/keila/q4/entregas/parte2-django/entrega10/test_api.py", line 145, in test_login_with_wrong_fields_400
    response = self.client.post("/api/login/", self.instructor_login_wrong_field, format="json")
  File "/home/keila/q4/entregas/parte2-django/entrega10/venv/lib/python3.9/site-packages/rest_framework/test.py", line 296, in post
    response = super().post(
  File "/home/keila/q4/entregas/parte2-django/entrega10/venv/lib/python3.9/site-packages/rest_framework/test.py", line 210, in post
    return self.generic('POST', path, data, content_type, **extra)
  File "/home/keila/q4/entregas/parte2-django/entrega10/venv/lib/python3.9/site-packages/rest_framework/test.py", line 234, in generic
    return super().generic(
  File "/home/keila/q4/entregas/parte2-django/entrega10/venv/lib/python3.9/site-packages/django/test/client.py", line 541, in generic
    return self.request(**r)
  File "/home/keila/q4/entregas/parte2-django/entrega10/venv/lib/python3.9/site-packages/rest_framework/test.py", line 286, in request
    return super().request(**kwargs)
  File "/home/keila/q4/entregas/parte2-django/entrega10/venv/lib/python3.9/site-packages/rest_framework/test.py", line 238, in request
    request = super().request(**kwargs)
  File "/home/keila/q4/entregas/parte2-django/entrega10/venv/lib/python3.9/site-packages/django/test/client.py", line 810, in request
    self.check_exception(response)
  File "/home/keila/q4/entregas/parte2-django/entrega10/venv/lib/python3.9/site-packages/django/test/client.py", line 663, in check_exception
    raise exc_value
  File "/home/keila/q4/entregas/parte2-django/entrega10/venv/lib/python3.9/site-packages/django/core/handlers/exception.py", line 55, in inner
    response = get_response(request)
  File "/home/keila/q4/entregas/parte2-django/entrega10/venv/lib/python3.9/site-packages/django/core/handlers/base.py", line 197, in _get_response
    response = wrapped_callback(request, *callback_args, **callback_kwargs)
  File "/home/keila/q4/entregas/parte2-django/entrega10/venv/lib/python3.9/site-packages/django/views/decorators/csrf.py", line 54, in wrapped_view
    return view_func(*args, **kwargs)
  File "/home/keila/q4/entregas/parte2-django/entrega10/venv/lib/python3.9/site-packages/django/views/generic/base.py", line 84, in view
    return self.dispatch(request, *args, **kwargs)
  File "/home/keila/q4/entregas/parte2-django/entrega10/venv/lib/python3.9/site-packages/rest_framework/views.py", line 511, in dispatch
    self.response = self.finalize_response(request, response, *args, **kwargs)
  File "/home/keila/q4/entregas/parte2-django/entrega10/venv/lib/python3.9/site-packages/rest_framework/views.py", line 423, in finalize_response
    assert isinstance(response, HttpResponseBase), (
AssertionError: Expected a `Response`, `HttpResponse` or `HttpStreamingResponse` to be returned from the view, but received a `<class 'int'>`

======================================================================
FAIL: test_wrong_data_user_creation_400 (test_api.TestAccountsRoutesWithoutAuthentication)
----------------------------------------------------------------------
Traceback (most recent call last):
  File "/home/keila/q4/entregas/parte2-django/entrega10/test_api.py", line 98, in test_wrong_data_user_creation_400
    response = self.client.post("/api/accounts/", self.instructor_wrong_data, format="json")
  File "/home/keila/q4/entregas/parte2-django/entrega10/venv/lib/python3.9/site-packages/rest_framework/test.py", line 296, in post
    response = super().post(
  File "/home/keila/q4/entregas/parte2-django/entrega10/venv/lib/python3.9/site-packages/rest_framework/test.py", line 210, in post
    return self.generic('POST', path, data, content_type, **extra)
  File "/home/keila/q4/entregas/parte2-django/entrega10/venv/lib/python3.9/site-packages/rest_framework/test.py", line 234, in generic
    return super().generic(
  File "/home/keila/q4/entregas/parte2-django/entrega10/venv/lib/python3.9/site-packages/django/test/client.py", line 541, in generic
    return self.request(**r)
  File "/home/keila/q4/entregas/parte2-django/entrega10/venv/lib/python3.9/site-packages/rest_framework/test.py", line 286, in request
    return super().request(**kwargs)
  File "/home/keila/q4/entregas/parte2-django/entrega10/venv/lib/python3.9/site-packages/rest_framework/test.py", line 238, in request
    request = super().request(**kwargs)
  File "/home/keila/q4/entregas/parte2-django/entrega10/venv/lib/python3.9/site-packages/django/test/client.py", line 810, in request
    self.check_exception(response)
  File "/home/keila/q4/entregas/parte2-django/entrega10/venv/lib/python3.9/site-packages/django/test/client.py", line 663, in check_exception
    raise exc_value
  File "/home/keila/q4/entregas/parte2-django/entrega10/venv/lib/python3.9/site-packages/django/core/handlers/exception.py", line 55, in inner
    response = get_response(request)
  File "/home/keila/q4/entregas/parte2-django/entrega10/venv/lib/python3.9/site-packages/django/core/handlers/base.py", line 197, in _get_response
    response = wrapped_callback(request, *callback_args, **callback_kwargs)
  File "/home/keila/q4/entregas/parte2-django/entrega10/venv/lib/python3.9/site-packages/django/views/decorators/csrf.py", line 54, in wrapped_view
    return view_func(*args, **kwargs)
  File "/home/keila/q4/entregas/parte2-django/entrega10/venv/lib/python3.9/site-packages/django/views/generic/base.py", line 84, in view
    return self.dispatch(request, *args, **kwargs)
  File "/home/keila/q4/entregas/parte2-django/entrega10/venv/lib/python3.9/site-packages/rest_framework/views.py", line 511, in dispatch
    self.response = self.finalize_response(request, response, *args, **kwargs)
  File "/home/keila/q4/entregas/parte2-django/entrega10/venv/lib/python3.9/site-packages/rest_framework/views.py", line 423, in finalize_response
    assert isinstance(response, HttpResponseBase), (
AssertionError: Expected a `Response`, `HttpResponse` or `HttpStreamingResponse` to be returned from the view, but received a `<class 'int'>`

======================================================================
FAIL: test_delete_course_by_instructor_204 (test_api.TestCourseDelete)
----------------------------------------------------------------------
Traceback (most recent call last):
  File "/home/keila/q4/entregas/parte2-django/entrega10/test_api.py", line 1088, in test_delete_course_by_instructor_204
    self.assertEqual(response.status_code, 204)
AssertionError: 405 != 204

======================================================================
FAIL: test_delete_course_by_no_user_401 (test_api.TestCourseDelete)
----------------------------------------------------------------------
Traceback (most recent call last):
  File "/home/keila/q4/entregas/parte2-django/entrega10/test_api.py", line 1120, in test_delete_course_by_no_user_401
    self.assertEqual(response.status_code, 401)
AssertionError: 405 != 401

======================================================================
FAIL: test_delete_course_by_student_403 (test_api.TestCourseDelete)
----------------------------------------------------------------------
Traceback (most recent call last):
  File "/home/keila/q4/entregas/parte2-django/entrega10/test_api.py", line 1106, in test_delete_course_by_student_403
    self.assertEqual(response.status_code, 403)
AssertionError: 405 != 403

======================================================================
FAIL: test_delete_course_with_invalid_course_id_404 (test_api.TestCourseDelete)
----------------------------------------------------------------------
Traceback (most recent call last):
  File "/home/keila/q4/entregas/parte2-django/entrega10/test_api.py", line 1140, in test_delete_course_with_invalid_course_id_404
    self.assertEqual(response.status_code, 404)
AssertionError: 405 != 404

======================================================================
FAIL: test_course_creation_by_instructor_201 (test_api.TestCoursesCreation)
----------------------------------------------------------------------
Traceback (most recent call last):
  File "/home/keila/q4/entregas/parte2-django/entrega10/test_api.py", line 257, in test_course_creation_by_instructor_201
    self.assertIn("instructor", output)
AssertionError: 'instructor' not found in {'uuid': '12eb9fca-f1ed-4264-9384-b60124b1e9ef', 'name': 'Django', 'demo_time': '09:00', 'created_at': '2022-03-16T02:39:38.850937Z', 'link_repo': 'https://gitlab.com/django_demos'}

======================================================================
FAIL: test_course_creation_by_no_user_401 (test_api.TestCoursesCreation)
----------------------------------------------------------------------
Traceback (most recent call last):
  File "/home/keila/q4/entregas/parte2-django/entrega10/test_api.py", line 284, in test_course_creation_by_no_user_401
    self.assertEqual(response.status_code, 401)
AssertionError: 201 != 401

======================================================================
FAIL: test_course_creation_by_student_403 (test_api.TestCoursesCreation)
----------------------------------------------------------------------
Traceback (most recent call last):
  File "/home/keila/q4/entregas/parte2-django/entrega10/test_api.py", line 270, in test_course_creation_by_student_403
    self.assertEqual(response.status_code, 403)
AssertionError: 201 != 403

======================================================================
FAIL: test_course_creation_wrong_data_400 (test_api.TestCoursesCreation)
----------------------------------------------------------------------
Traceback (most recent call last):
  File "/home/keila/q4/entregas/parte2-django/entrega10/test_api.py", line 316, in test_course_creation_wrong_data_400
    response = self.client.post("/api/courses/", self.course_data_wrong, format="json")
  File "/home/keila/q4/entregas/parte2-django/entrega10/venv/lib/python3.9/site-packages/rest_framework/test.py", line 296, in post
    response = super().post(
  File "/home/keila/q4/entregas/parte2-django/entrega10/venv/lib/python3.9/site-packages/rest_framework/test.py", line 210, in post
    return self.generic('POST', path, data, content_type, **extra)
  File "/home/keila/q4/entregas/parte2-django/entrega10/venv/lib/python3.9/site-packages/rest_framework/test.py", line 234, in generic
    return super().generic(
  File "/home/keila/q4/entregas/parte2-django/entrega10/venv/lib/python3.9/site-packages/django/test/client.py", line 541, in generic
    return self.request(**r)
  File "/home/keila/q4/entregas/parte2-django/entrega10/venv/lib/python3.9/site-packages/rest_framework/test.py", line 286, in request
    return super().request(**kwargs)
  File "/home/keila/q4/entregas/parte2-django/entrega10/venv/lib/python3.9/site-packages/rest_framework/test.py", line 238, in request
    request = super().request(**kwargs)
  File "/home/keila/q4/entregas/parte2-django/entrega10/venv/lib/python3.9/site-packages/django/test/client.py", line 810, in request
    self.check_exception(response)
  File "/home/keila/q4/entregas/parte2-django/entrega10/venv/lib/python3.9/site-packages/django/test/client.py", line 663, in check_exception
    raise exc_value
  File "/home/keila/q4/entregas/parte2-django/entrega10/venv/lib/python3.9/site-packages/django/core/handlers/exception.py", line 55, in inner
    response = get_response(request)
  File "/home/keila/q4/entregas/parte2-django/entrega10/venv/lib/python3.9/site-packages/django/core/handlers/base.py", line 197, in _get_response
    response = wrapped_callback(request, *callback_args, **callback_kwargs)
  File "/home/keila/q4/entregas/parte2-django/entrega10/venv/lib/python3.9/site-packages/django/views/decorators/csrf.py", line 54, in wrapped_view
    return view_func(*args, **kwargs)
  File "/home/keila/q4/entregas/parte2-django/entrega10/venv/lib/python3.9/site-packages/django/views/generic/base.py", line 84, in view
    return self.dispatch(request, *args, **kwargs)
  File "/home/keila/q4/entregas/parte2-django/entrega10/venv/lib/python3.9/site-packages/rest_framework/views.py", line 511, in dispatch
    self.response = self.finalize_response(request, response, *args, **kwargs)
  File "/home/keila/q4/entregas/parte2-django/entrega10/venv/lib/python3.9/site-packages/rest_framework/views.py", line 423, in finalize_response
    assert isinstance(response, HttpResponseBase), (
AssertionError: Expected a `Response`, `HttpResponse` or `HttpStreamingResponse` to be returned from the view, but received a `<class 'int'>`

======================================================================
FAIL: test_retrieve_valid_course_200 (test_api.TestCoursesCreation)
----------------------------------------------------------------------
Traceback (most recent call last):
  File "/home/keila/q4/entregas/parte2-django/entrega10/test_api.py", line 366, in test_retrieve_valid_course_200
    self.assertEqual(output, course)
AssertionError: {'uui[76 chars]09:00:00', 'created_at': '2022-03-16T02:39:42.[52 chars]mos'} != {'uui[76 chars]09:00', 'created_at': '2022-03-16T02:39:42.831[49 chars]mos'}
  {'created_at': '2022-03-16T02:39:42.831901Z',
-  'demo_time': '09:00:00',
?                     ---

+  'demo_time': '09:00',
   'link_repo': 'https://gitlab.com/django_demos',
   'name': 'Django',
   'uuid': '0de2b067-5c12-40af-a6d0-04f02d080f2a'}

======================================================================
FAIL: test_update_course_by_instructor_200 (test_api.TestCoursesUpdate)
----------------------------------------------------------------------
Traceback (most recent call last):
  File "/home/keila/q4/entregas/parte2-django/entrega10/test_api.py", line 448, in test_update_course_by_instructor_200
    self.assertEqual(response.status_code, 200)
AssertionError: 405 != 200

======================================================================
FAIL: test_update_course_by_no_user_401 (test_api.TestCoursesUpdate)
----------------------------------------------------------------------
Traceback (most recent call last):
  File "/home/keila/q4/entregas/parte2-django/entrega10/test_api.py", line 479, in test_update_course_by_no_user_401
    self.assertEqual(response.status_code, 401)
AssertionError: 405 != 401

======================================================================
FAIL: test_update_course_by_student_403 (test_api.TestCoursesUpdate)
----------------------------------------------------------------------
Traceback (most recent call last):
  File "/home/keila/q4/entregas/parte2-django/entrega10/test_api.py", line 463, in test_update_course_by_student_403
    self.assertEqual(response.status_code, 403)
AssertionError: 405 != 403

======================================================================
FAIL: test_update_course_with_conflict_422 (test_api.TestCoursesUpdate)
----------------------------------------------------------------------
Traceback (most recent call last):
  File "/home/keila/q4/entregas/parte2-django/entrega10/test_api.py", line 524, in test_update_course_with_conflict_422
    self.assertEqual(response.status_code, 422)
AssertionError: 405 != 422

======================================================================
FAIL: test_update_invalid_course_404 (test_api.TestCoursesUpdate)
----------------------------------------------------------------------
Traceback (most recent call last):
  File "/home/keila/q4/entregas/parte2-django/entrega10/test_api.py", line 499, in test_update_invalid_course_404
    self.assertEqual(response.status_code, 404)
AssertionError: 405 != 404

----------------------------------------------------------------------
Ran 45 tests in 29.640s

FAILED (failures=16, errors=19)
Destroying test database for alias 'default' ('file:memorydb_default?mode=memory&cache=shared')...
